<?xml version="1.0" encoding="utf-8"?>
<!-- This URDF was automatically created by SolidWorks to URDF Exporter! Originally created by Stephen Brawner (brawner@gmail.com) 
     Commit Version: 1.6.0-4-g7f85cfe  Build Version: 1.6.7995.38578
     For more information, please see http://wiki.ros.org/sw_urdf_exporter -->
<robot
  name="wheele">
  <link
    name="base_link">
    <inertial>
      <origin
        xyz="-0.0527414453514239 -1.08270102171606E-06 0.207668676561577"
        rpy="0 0 0" />
      <mass
        value="91.1648574707324" />
      <inertia
        ixx="3.16732019149984"
        ixy="4.74759163822853E-05"
        ixz="-0.32026788285614"
        iyy="3.23556377175086"
        iyz="1.49370499763038E-05"
        izz="3.88981086562858" />
    </inertial>
    <visual>
      <origin
        xyz="0 0 0"
        rpy="0 0 0" />
      <geometry>
        <mesh
          filename="package://wheele_description/meshes/base_link.STL" />
      </geometry>
      <material
        name="">
        <color
          rgba="0.792156862745098 0.819607843137255 0.933333333333333 1" />
      </material>
    </visual>
    <collision>
      <origin
        xyz="0 0 0"
        rpy="0 0 0" />
      <geometry>
        <mesh
          filename="package://wheele_description/meshes/base_link.STL" />
      </geometry>
    </collision>
  </link>
  <link
    name="wheel_back_left">
    <inertial>
      <origin
        xyz="0.000123919025762947 -0.0375 -0.00194200173946403"
        rpy="1.570796 0 0" />
      <mass
        value="6.60646736275211" />
      <inertia
        ixx="0.0537442322482938"
        ixy="2.16892957827706E-19"
        ixz="-9.1019815591947E-05"
        iyy="0.102710694072585"
        iyz="8.57940734504454E-20"
        izz="0.0551600249768718" />
    </inertial>
    <visual>
      <origin
        xyz="0.000123919025762947 -0.0375 -0.00194200173946403"
        rpy="1.570796 0 0" />
      <geometry>
        <cylinder length="0.075" radius="0.1725" />
      </geometry>
      <material
        name="">
        <color
          rgba="0.792156862745098 0.819607843137255 0.933333333333333 1" />
      </material>
    </visual>
    <collision>
      <origin
        xyz="0.000123919025762947 -0.0375 -0.00194200173946403"
        rpy="1.570796 0 0" />
      <geometry>
        <cylinder length="0.075" radius="0.1725" />
      </geometry>
    </collision>
  </link>
  <joint
    name="joint_wheel_back_left"
    type="continuous">
    <origin
      xyz="-0.189 0.33 0.0885"
      rpy="0 0 0" />
    <parent
      link="base_link" />
    <child
      link="wheel_back_left" />
    <axis
      xyz="0 1 0" />
    <limit
      effort="30"
      velocity="30" />
  </joint>
  <link
    name="wheel_back_right">
    <inertial>
      <origin
        xyz="-8.2629885896357E-06 0.0375 -0.00194593381286387"
        rpy="1.570796 0 0" />
      <mass
        value="6.60646736275211" />
      <inertia
        ixx="0.0537384278699751"
        ixy="-2.83252785110274E-19"
        ixz="5.75494615143155E-06"
        iyy="0.102710694072585"
        iyz="-5.47735900067466E-22"
        izz="0.0551658293551905" />
    </inertial>
    <visual>
      <origin
        xyz="-8.2629885896357E-06 0.0375 -0.00194593381286387"
        rpy="1.570796 0 0" />
      <geometry>
        <cylinder length="0.075" radius="0.1725" />
      </geometry>
      <material
        name="">
        <color
          rgba="0.792156862745098 0.819607843137255 0.933333333333333 1" />
      </material>
    </visual>
    <collision>
      <origin
        xyz="-8.2629885896357E-06 0.0375 -0.00194593381286387"
        rpy="1.570796 0 0" />
      <geometry>
        <cylinder length="0.075" radius="0.1725" />
      </geometry>
    </collision>
  </link>
  <joint
    name="joint_wheel_back_right"
    type="continuous">
    <origin
      xyz="-0.189 -0.33 0.0885"
      rpy="0 0 0" />
    <parent
      link="base_link" />
    <child
      link="wheel_back_right" />
    <axis
      xyz="0 1 0" />
    <limit
      effort="30"
      velocity="30" />
  </joint>
  <link
    name="front_right">
    <inertial>
      <origin
        xyz="-0.00796967411895133 1.34484746663888E-05 -0.169078862100503"
        rpy="0 0 0" />
      <mass
        value="0.912192812599195" />
      <inertia
        ixx="0.0138058169636317"
        ixy="5.46192947538833E-07"
        ixz="-0.00150025951095099"
        iyy="0.0140839705934447"
        iyz="2.76870935230375E-06"
        izz="0.00126687371083358" />
    </inertial>
    <visual>
      <origin
        xyz="0 0 0"
        rpy="0 0 0" />
      <geometry>
        <mesh
          filename="package://wheele_description/meshes/front_right.STL" />
      </geometry>
      <material
        name="">
        <color
          rgba="0.792156862745098 0.819607843137255 0.933333333333333 1" />
      </material>
    </visual>
    <collision>
      <origin
        xyz="0 0 0"
        rpy="0 0 0" />
      <geometry>
        <mesh
          filename="package://wheele_description/meshes/front_right.STL" />
      </geometry>
    </collision>
  </link>
  <joint
    name="jont_front_right"
    type="continuous">
    <origin
      xyz="0.42825 -0.21075 0.394"
      rpy="0 0 0" />
    <parent
      link="base_link" />
    <child
      link="front_right" />
    <axis
      xyz="0 0 -1" />
  </joint>
  <link
    name="wheel_front_right">
    <inertial>
      <origin
        xyz="-0.000134044498266039 0.0325 -0.00152009362232607"
        rpy="1.570796 0 0" />
      <mass
        value="1.54915886155044" />
      <inertia
        ixx="0.00448990415075851"
        ixy="-2.74052534042467E-18"
        ixz="1.41226640854449E-05"
        iyy="0.00849384204724026"
        iyz="2.18087529975426E-19"
        izz="0.00464942075546111" />
    </inertial>
    <visual>
      <origin
        xyz="-0.000134044498266039 0.0325 -0.00152009362232607"
        rpy="1.570796 0 0" />
      <geometry>
        <cylinder length="0.05" radius="0.1025" />
      </geometry>
      <material
        name="">
        <color
          rgba="0.792156862745098 0.819607843137255 0.933333333333333 1" />
      </material>
    </visual>
    <collision>
      <origin
        xyz="-0.000134044498266039 0.0325 -0.00152009362232607"
        rpy="1.570796 0 0" />
      <geometry>
        <cylinder length="0.05" radius="0.1025" />
      </geometry>
    </collision>
  </link>
  <joint
    name="joint_wheel_front_right"
    type="continuous">
    <origin
      xyz="-0.075 -0.035 -0.3755"
      rpy="0 0 0" />
    <parent
      link="front_right" />
    <child
      link="wheel_front_right" />
    <axis
      xyz="0 -1 0" />
  </joint>
  <link
    name="front_left">
    <inertial>
      <origin
        xyz="-0.00796967411880023 1.34484745151486E-05 -0.169078862100503"
        rpy="0 0 0" />
      <mass
        value="0.912192812599195" />
      <inertia
        ixx="0.0138058169636317"
        ixy="5.46192947538824E-07"
        ixz="-0.00150025951095099"
        iyy="0.0140839705934447"
        iyz="2.76870935230368E-06"
        izz="0.00126687371083358" />
    </inertial>
    <visual>
      <origin
        xyz="0 0 0"
        rpy="0 0 0" />
      <geometry>
        <mesh
          filename="package://wheele_description/meshes/front_left.STL" />
      </geometry>
      <material
        name="">
        <color
          rgba="0.792156862745098 0.819607843137255 0.933333333333333 1" />
      </material>
    </visual>
    <collision>
      <origin
        xyz="0 0 0"
        rpy="0 0 0" />
      <geometry>
        <mesh
          filename="package://wheele_description/meshes/front_left.STL" />
      </geometry>
    </collision>
  </link>
  <joint
    name="joint_front_left"
    type="continuous">
    <origin
      xyz="0.42825 0.21125 0.394"
      rpy="0 0 0" />
    <parent
      link="base_link" />
    <child
      link="front_left" />
    <axis
      xyz="0 0 -1" />
  </joint>
  <link
    name="wheel_front_left">
    <inertial>
      <origin
        xyz="-0.00106531226090795 -0.0325 -0.00109259431396592"
        rpy="1.570796 0 0" />
      <mass
        value="1.54915886155044" />
      <inertia
        ixx="0.00456756149249647"
        ixy="-1.69951829350563E-18"
        ixz="8.09717382753578E-05"
        iyy="0.00849384204724026"
        iyz="-5.55422993037582E-19"
        izz="0.00457176341372314" />
    </inertial>
    <visual>
      <origin
        xyz="-0.00106531226090795 -0.0325 -0.00109259431396592"
        rpy="1.570796 0 0" />
      <geometry>
        <cylinder length="0.05" radius="0.1025" />
      </geometry>
      <material
        name="">
        <color
          rgba="0.792156862745098 0.819607843137255 0.933333333333333 1" />
      </material>
    </visual>
    <collision>
      <origin
        xyz="-0.00106531226090795 -0.0325 -0.00109259431396592"
        rpy="1.570796 0 0" />
      <geometry>
        <cylinder length="0.05" radius="0.1025" />
      </geometry>
    </collision>
  </link>
  <joint
    name="joint_wheel_front_left"
    type="continuous">
    <origin
      xyz="-0.075 0.035 -0.3755"
      rpy="0 0 0" />
    <parent
      link="front_left" />
    <child
      link="wheel_front_left" />
    <axis
      xyz="0 -1 0" />
  </joint>

  <link name="dummy">
  </link>
  <joint name="dummy_joint" type="fixed">
     <parent link="dummy"/>
     <child link="base_link"/>
  </joint>

  <joint name="camera_joint" type="fixed">
    <parent link="base_link"/>
    <child link="camera_link"/>
    <origin xyz="0.145 0 0.08" rpy="0 0 0"/>
  </joint>

  <link name="camera_link">
    <visual>
      <geometry>
        <box size="0.010 0.03 0.03"/>
      </geometry>
    </visual>
  </link>

  <gazebo reference="camera_link">
    <sensor name="camera" type="depth">
      <update_rate>20</update_rate>
      <pose> 0 0 0 0 0 0 </pose>
      <visualize>true</visualize>
      <camera>
        <horizontal_fov>1.047198</horizontal_fov>
        <image>
          <width>640</width>
          <height>480</height>
          <format>R8G8B8</format>
        </image>
        <clip>
          <near>0.05</near>
          <far>3</far>
        </clip>
      </camera>

      <plugin name="camera_plugin" filename="libgazebo_ros_openni_kinect.so">
        <baseline>0.2</baseline>
        <alwaysOn>true</alwaysOn>
        <!-- Keep this zero, update_rate in the parent <sensor> tag
          will control the frame rate. -->
        <updateRate>0.0</updateRate>
        <cameraName>camera_ir</cameraName>
        <imageTopicName>/camera/color/image_raw</imageTopicName>
        <cameraInfoTopicName>/camera/color/camera_info</cameraInfoTopicName>
        <depthImageTopicName>/camera/depth/image_raw</depthImageTopicName>
        <depthImageCameraInfoTopicName>/camera/depth/camera_info</depthImageCameraInfoTopicName>
        <pointCloudTopicName>/camera/depth/points</pointCloudTopicName>
        <frameName>camera_link</frameName>
        <pointCloudCutoff>0.5</pointCloudCutoff>
        <pointCloudCutoffMax>3.0</pointCloudCutoffMax>
        <distortionK1>0</distortionK1>
        <distortionK2>0</distortionK2>
        <distortionK3>0</distortionK3>
        <distortionT1>0</distortionT1>
        <distortionT2>0</distortionT2>
        <CxPrime>0</CxPrime>
        <Cx>0</Cx>
        <Cy>0</Cy>
        <focalLength>0</focalLength>
        <hackBaseline>0</hackBaseline>
      </plugin>
    </sensor>
  </gazebo> 

  <gazebo> 
    <plugin name="odom_plugin" filename="libgazebo_ros_p3d.so">
      <alwaysOn>true</alwaysOn>
      <updateRate>50.0</updateRate>
      <bodyName>base_link</bodyName>
      <topicName>/odom</topicName>
      <gaussianNoise>0.0</gaussianNoise>
      <frameName>map</frameName>
    </plugin>
  </gazebo> 

  <transmission name="tran_wheel_back_right">
    <type>transmission_interface/SimpleTransmission</type>
    <joint name="joint_wheel_back_right">
      <hardwareInterface>hardware_interface/VelocityJointInterface</hardwareInterface>
    </joint>
    <actuator name="motor_wheel_back_right">
      <hardwareInterface>hardware_interface/VelocityJointInterface</hardwareInterface>
      <mechanicalReduction>1</mechanicalReduction>
    </actuator>
  </transmission>

  <transmission name="tran_wheel_back_left">
    <type>transmission_interface/SimpleTransmission</type>
    <joint name="joint_wheel_back_left">
      <hardwareInterface>hardware_interface/VelocityJointInterface</hardwareInterface>
    </joint>
    <actuator name="motor_wheel_back_left">
      <hardwareInterface>hardware_interface/VelocityJointInterface</hardwareInterface>
      <mechanicalReduction>1</mechanicalReduction>
    </actuator>
  </transmission>

  <gazebo>
    <plugin name="gazebo_ros_control" filename="libgazebo_ros_control.so">
      <robotNamespace>/wheele</robotNamespace>
    </plugin>
  </gazebo>


</robot>