<?xml version="1.0" encoding="utf-8"?>
<!-- This URDF was automatically created by SolidWorks to URDF Exporter! Originally created by Stephen Brawner (brawner@gmail.com) 
     Commit Version: 1.6.0-4-g7f85cfe  Build Version: 1.6.7995.38578
     For more information, please see http://wiki.ros.org/sw_urdf_exporter -->
<robot
  name="wheele">
  <link
    name="base_link">
    <inertial>
      <origin
        xyz="-0.036424 0.011524 0.45653"
        rpy="0 0 0" />
      <mass
        value="245.00" />
      <inertia
        ixx="8.5549"
        ixy="0.00012862"
        ixz="-0.86804"
        iyy="8.7476"
        iyz="4.0322E-05"
        izz="10.515" />
    </inertial>
    <visual>
      <origin
        xyz="0 0 0"
        rpy="0 0 0" />
      <geometry>
        <mesh
          filename="package://wheele_description/meshes/base_link.STL" />
      </geometry>
      <material
        name="">
        <color
          rgba="0.79216 0.81961 0.93333 1" />
      </material>
    </visual>
    <collision>
      <origin
        xyz="0 0 0"
        rpy="0 0 0" />
      <geometry>
        <mesh
          filename="package://wheele_description/meshes/base_link.STL" />
      </geometry>
    </collision>
  </link>
  <link
    name="pivot_fr">
    <inertial>
      <origin
        xyz="-0.0079697 1.3448E-05 -0.16908"
        rpy="0 0 0" />
      <mass
        value="2.4629" />
      <inertia
        ixx="0.037276"
        ixy="1.4747E-06"
        ixz="-0.0040507"
        iyy="0.038027"
        iyz="7.4755E-06"
        izz="0.0034206" />
    </inertial>
    <visual>
      <origin
        xyz="0 0 0"
        rpy="0 0 0" />
      <geometry>
        <mesh
          filename="package://wheele_description/meshes/pivot_fr.STL" />
      </geometry>
      <material
        name="">
        <color
          rgba="0.79216 0.81961 0.93333 1" />
      </material>
    </visual>
    <collision>
      <origin
        xyz="0 0 0"
        rpy="0 0 0" />
      <geometry>
        <mesh
          filename="package://wheele_description/meshes/pivot_fr.STL" />
      </geometry>
    </collision>
  </link>
  <joint
    name="joint_pivot_fr"
    type="continuous">
    <origin
      xyz="0.429988943278938 -0.210751292864914 0.394"
      rpy="0 0 0" />
    <parent
      link="base_link" />
    <child
      link="pivot_fr" />
    <axis
      xyz="0 0 -1" />
  </joint>
  <link
    name="wheel_fr">
    <inertial>
      <origin
        xyz="-0.00013404 0.0325 -0.0015201"
        rpy="1.57079 0 0" />
      <mass
        value="2.0759" />
      <inertia
        ixx="0.0060148"
        ixy="-1.8758E-17"
        ixz="8.4658E-07"
        iyy="0.011382"
        iyz="8.8969E-21"
        izz="0.0062319" />
    </inertial>
    <visual>
      <origin
        xyz="-0.00013404 0.0325 -0.0015201"
        rpy="1.57079 0 0" />
      <geometry>
        <cylinder length="0.05" radius="0.1025" />
      </geometry>
      <material
        name="">
        <color
          rgba="0.79216 0.81961 0.93333 1" />
      </material>
    </visual>
    <collision>
      <origin
        xyz="-0.00013404 0.0325 -0.0015201"
        rpy="1.57079 0 0" />
      <geometry>
        <cylinder length="0.05" radius="0.1025" />
      </geometry>
    </collision>
  </link>
  <joint
    name="joint_wheel_fr"
    type="continuous">
    <origin
      xyz="-0.0749999999998487 -0.035000000000324 -0.3755"
      rpy="0 0 0" />
    <parent
      link="pivot_fr" />
    <child
      link="wheel_fr" />
    <axis
      xyz="0 -1 0" />
  </joint>
  <link
    name="pivot_fl">
    <inertial>
      <origin
        xyz="-0.0079697 1.3448E-05 -0.16908"
        rpy="0 0 0" />
      <mass
        value="2.4629" />
      <inertia
        ixx="0.037276"
        ixy="1.4747E-06"
        ixz="-0.0040507"
        iyy="0.038027"
        iyz="7.4755E-06"
        izz="0.0034206" />
    </inertial>
    <visual>
      <origin
        xyz="0 0 0"
        rpy="0 0 0" />
      <geometry>
        <mesh
          filename="package://wheele_description/meshes/pivot_fl.STL" />
      </geometry>
      <material
        name="">
        <color
          rgba="0.79216 0.81961 0.93333 1" />
      </material>
    </visual>
    <collision>
      <origin
        xyz="0 0 0"
        rpy="0 0 0" />
      <geometry>
        <mesh
          filename="package://wheele_description/meshes/pivot_fl.STL" />
      </geometry>
    </collision>
  </link>
  <joint
    name="joint_pivot_fl"
    type="continuous">
    <origin
      xyz="0.429988943278938 0.21125 0.394"
      rpy="0 0 0" />
    <parent
      link="base_link" />
    <child
      link="pivot_fl" />
    <axis
      xyz="0 0 -1" />
  </joint>
  <link
    name="wheel_fl">
    <inertial>
      <origin
        xyz="-0.0010653 -0.0325 -0.0010926"
        rpy="1.57079 0 0" />
      <mass
        value="2.0759" />
      <inertia
        ixx="0.0060374"
        ixy="-2.3306E-18"
        ixz="6.625E-05"
        iyy="0.011382"
        iyz="-6.1376E-19"
        izz="0.0062093" />
    </inertial>
    <visual>
      <origin
        xyz="-0.0010653 -0.0325 -0.0010926"
        rpy="1.57079 0 0" />
      <geometry>
        <cylinder length="0.05" radius="0.1025" />
      </geometry>
      <material
        name="">
        <color
          rgba="0.79216 0.81961 0.93333 1" />
      </material>
    </visual>
    <collision>
      <origin
        xyz="-0.0010653 -0.0325 -0.0010926"
        rpy="1.57079 0 0" />
      <geometry>
        <cylinder length="0.05" radius="0.1025" />
      </geometry>
    </collision>
  </link>
  <joint
    name="joint_wheel_fl"
    type="continuous">
    <origin
      xyz="-0.075 0.035 -0.3755"
      rpy="0 0 0" />
    <parent
      link="pivot_fl" />
    <child
      link="wheel_fl" />
    <axis
      xyz="0 -1 0" />
  </joint>
  <link
    name="wheel_br">
    <inertial>
      <origin
        xyz="-8.263E-06 0.0375 -0.0019459"
        rpy="1.57079 0 0" />
      <mass
        value="8.8527" />
      <inertia
        ixx="0.072009"
        ixy="-2.2909E-16"
        ixz="7.7116E-06"
        iyy="0.13763"
        iyz="-3.498E-19"
        izz="0.073922" />
    </inertial>
    <visual>
      <origin
        xyz="-8.263E-06 0.0375 -0.0019459"
        rpy="1.57079 0 0" />
      <geometry>
        <cylinder length="0.075" radius="0.1725" />
      </geometry>
      <material
        name="">
        <color
          rgba="0.79216 0.81961 0.93333 1" />
      </material>
    </visual>
    <collision>
      <origin
        xyz="-8.263E-06 0.0375 -0.0019459"
        rpy="1.57079 0 0" />
      <geometry>
        <cylinder length="0.075" radius="0.1725" />
      </geometry>
    </collision>
  </link>
  <joint
    name="joint_wheel_br"
    type="continuous">
    <origin
      xyz="-0.189 -0.33 0.0885"
      rpy="0 0 0" />
    <parent
      link="base_link" />
    <child
      link="wheel_br" />
    <axis
      xyz="0 1 0" />
  </joint>
  <link
    name="wheel_bl">
    <inertial>
      <origin
        xyz="8.263E-06 -0.0375 -0.0019459"
        rpy="1.57079 0 0" />
      <mass
        value="8.8527" />
      <inertia
        ixx="0.072026"
        ixy="9.6405E-19"
        ixz="-0.00017836"
        iyy="0.13763"
        iyz="1.51E-19"
        izz="0.073905" />
    </inertial>
    <visual>
      <origin
        xyz="8.263E-06 -0.0375 -0.0019459"
        rpy="1.57079 0 0" />
      <geometry>
        <cylinder length="0.075" radius="0.1725" />
      </geometry>
      <material
        name="">
        <color
          rgba="0.79216 0.81961 0.93333 1" />
      </material>
    </visual>
    <collision>
      <origin
        xyz="8.263E-06 -0.0375 -0.0019459"
        rpy="1.57079 0 0" />
      <geometry>
        <cylinder length="0.075" radius="0.1725" />
      </geometry>
    </collision>
  </link>
  <joint
    name="joint_wheel_bl"
    type="continuous">
    <origin
      xyz="-0.189 0.33 0.0885"
      rpy="0 0 0" />
    <parent
      link="base_link" />
    <child
      link="wheel_bl" />
    <axis
      xyz="0 1 0" />
  </joint>


  // ---- GAZEBO ----

  <link name="dummy">
  </link>
  <joint name="dummy_joint" type="fixed">
     <parent link="dummy"/>
     <child link="base_link"/>
  </joint>

  <joint name="camera_joint" type="fixed">
    <parent link="base_link"/>
    <child link="camera_link"/>
    <origin xyz="0.38 0 0.48" rpy="0 0 0"/>
  </joint>

  <link name="camera_link">
    <visual>
      <geometry>
        <box size="0.010 0.03 0.03"/>
      </geometry>
    </visual>
  </link>

  <gazebo reference="camera_link">
    <sensor name="camera" type="depth">
      <update_rate>20</update_rate>
      <pose> 0 0 0 0 0 0 </pose>
      <visualize>true</visualize>
      <camera>
        <horizontal_fov>1.047198</horizontal_fov>
        <image>
          <width>640</width>
          <height>480</height>
          <format>R8G8B8</format>
        </image>
        <clip>
          <near>0.05</near>
          <far>5</far>
        </clip>
      </camera>

      <plugin name="camera_plugin" filename="libgazebo_ros_openni_kinect.so">
        <baseline>0.2</baseline>
        <alwaysOn>true</alwaysOn>
        <!-- Keep this zero, update_rate in the parent <sensor> tag
          will control the frame rate. -->
        <updateRate>0.0</updateRate>
        <cameraName>camera_ir</cameraName>
        <imageTopicName>/camera/color/image_raw</imageTopicName>
        <cameraInfoTopicName>/camera/color/camera_info</cameraInfoTopicName>
        <depthImageTopicName>/camera/depth/image_raw</depthImageTopicName>
        <depthImageCameraInfoTopicName>/camera/depth/camera_info</depthImageCameraInfoTopicName>
        <pointCloudTopicName>/camera/depth/points</pointCloudTopicName>
        <frameName>camera_link</frameName>
        <pointCloudCutoff>0.5</pointCloudCutoff>
        <pointCloudCutoffMax>5.0</pointCloudCutoffMax>
        <distortionK1>0</distortionK1>
        <distortionK2>0</distortionK2>
        <distortionK3>0</distortionK3>
        <distortionT1>0</distortionT1>
        <distortionT2>0</distortionT2>
        <CxPrime>0</CxPrime>
        <Cx>0</Cx>
        <Cy>0</Cy>
        <focalLength>0</focalLength>
        <hackBaseline>0</hackBaseline>
      </plugin>
    </sensor>
  </gazebo> 

  <gazebo> 
    <plugin name="odom_plugin" filename="libgazebo_ros_p3d.so">
      <alwaysOn>true</alwaysOn>
      <updateRate>50.0</updateRate>
      <bodyName>base_link</bodyName>
      <topicName>/odom</topicName>
      <gaussianNoise>0.0</gaussianNoise>
      <frameName>map</frameName>
    </plugin>
  </gazebo> 

  <transmission name="tran_wheel_back_right">
    <type>transmission_interface/SimpleTransmission</type>
    <joint name="joint_wheel_br">
      <hardwareInterface>hardware_interface/VelocityJointInterface</hardwareInterface>
    </joint>
    <actuator name="motor_wheel_back_right">
      <hardwareInterface>hardware_interface/VelocityJointInterface</hardwareInterface>
      <mechanicalReduction>1</mechanicalReduction>
    </actuator>
  </transmission>

  <transmission name="tran_wheel_back_left">
    <type>transmission_interface/SimpleTransmission</type>
    <joint name="joint_wheel_bl">
      <hardwareInterface>hardware_interface/VelocityJointInterface</hardwareInterface>
    </joint>
    <actuator name="motor_wheel_back_left">
      <hardwareInterface>hardware_interface/VelocityJointInterface</hardwareInterface>
      <mechanicalReduction>1</mechanicalReduction>
    </actuator>
  </transmission>

  <gazebo>
    <plugin name="gazebo_ros_control" filename="libgazebo_ros_control.so">
      <robotNamespace>/wheele</robotNamespace>
    </plugin>
  </gazebo>

</robot>